<?xml version="1.0"?>
<robot name="robbie">

    <!-- Base (Box-like structure) -->
    <link name="base">
        <visual>
            <origin xyz="0 0 0" rpy="0 0 0"/>
            <geometry>
                <box size="0.5 0.5 0.1"/>
            </geometry>
            <material name="yellow">
                <color rgba="1 1 0 1"/>
            </material>
        </visual>
    </link>

    <!-- Joint for e1 (yaw) -->
    <joint name="e1_joint" type="revolute">
        <parent link="base"/>
        <child link="e1"/>
        <origin xyz="0 0 0.1" rpy="0 0 0"/>
        <axis xyz="0 0 1"/>
        <limit lower="-3.14" upper="3.14" effort="10.0" velocity="1.0"/>
    </joint>

    <!-- e1 (pitch) -->
    <link name="e1">
        <visual>
            <origin xyz="0 0 0" rpy="0 0 0"/>
            <geometry>
                <box size="0.5 0.5 0.1"/>
            </geometry>
            <material name="yellow">
                <color rgba="1 1 0 1"/>
            </material>
        </visual>
    </link>
</robot>